2023-10-19 00:22:04,737 - telegram.ext.Application - ERROR - No error handlers are registered, logging exception.
Traceback (most recent call last):
  File "/Users/nikita/PycharmProjects/pythonProject/venv/lib/python3.11/site-packages/telegram/ext/_application.py", line 1195, in process_update
    await coroutine
  File "/Users/nikita/PycharmProjects/pythonProject/venv/lib/python3.11/site-packages/telegram/ext/_basehandler.py", line 153, in handle_update
    return await self.callback(update, context)
           ^^^^^^^^^^^^^^^^^^^^^^^^^^^^^^^^^^^^
TypeError: object NoneType can't be used in 'await' expression
2023-10-19 00:22:06,346 - telegram.ext.Application - ERROR - No error handlers are registered, logging exception.
Traceback (most recent call last):
  File "/Users/nikita/PycharmProjects/pythonProject/venv/lib/python3.11/site-packages/telegram/ext/_application.py", line 1195, in process_update
    await coroutine
  File "/Users/nikita/PycharmProjects/pythonProject/venv/lib/python3.11/site-packages/telegram/ext/_basehandler.py", line 153, in handle_update
    return await self.callback(update, context)
           ^^^^^^^^^^^^^^^^^^^^^^^^^^^^^^^^^^^^
TypeError: object NoneType can't be used in 'await' expression
2023-10-19 00:22:07,337 - telegram.ext.Application - ERROR - No error handlers are registered, logging exception.
Traceback (most recent call last):
  File "/Users/nikita/PycharmProjects/pythonProject/venv/lib/python3.11/site-packages/telegram/ext/_application.py", line 1195, in process_update
    await coroutine
  File "/Users/nikita/PycharmProjects/pythonProject/venv/lib/python3.11/site-packages/telegram/ext/_basehandler.py", line 153, in handle_update
    return await self.callback(update, context)
           ^^^^^^^^^^^^^^^^^^^^^^^^^^^^^^^^^^^^
TypeError: object NoneType can't be used in 'await' expression
2023-10-19 00:22:40,042 - telegram.ext.Application - ERROR - No error handlers are registered, logging exception.
Traceback (most recent call last):
  File "/Users/nikita/PycharmProjects/pythonProject/venv/lib/python3.11/site-packages/telegram/ext/_application.py", line 1195, in process_update
    await coroutine
  File "/Users/nikita/PycharmProjects/pythonProject/venv/lib/python3.11/site-packages/telegram/ext/_basehandler.py", line 153, in handle_update
    return await self.callback(update, context)
           ^^^^^^^^^^^^^^^^^^^^^^^^^^^^^^^^^^^^
TypeError: object NoneType can't be used in 'await' expression
2023-10-19 00:22:41,553 - telegram.ext.Application - ERROR - No error handlers are registered, logging exception.
Traceback (most recent call last):
  File "/Users/nikita/PycharmProjects/pythonProject/venv/lib/python3.11/site-packages/telegram/ext/_application.py", line 1195, in process_update
    await coroutine
  File "/Users/nikita/PycharmProjects/pythonProject/venv/lib/python3.11/site-packages/telegram/ext/_basehandler.py", line 153, in handle_update
    return await self.callback(update, context)
           ^^^^^^^^^^^^^^^^^^^^^^^^^^^^^^^^^^^^
TypeError: object NoneType can't be used in 'await' expression
2023-10-19 00:22:42,353 - telegram.ext.Application - ERROR - No error handlers are registered, logging exception.
Traceback (most recent call last):
  File "/Users/nikita/PycharmProjects/pythonProject/venv/lib/python3.11/site-packages/telegram/ext/_application.py", line 1195, in process_update
    await coroutine
  File "/Users/nikita/PycharmProjects/pythonProject/venv/lib/python3.11/site-packages/telegram/ext/_basehandler.py", line 153, in handle_update
    return await self.callback(update, context)
           ^^^^^^^^^^^^^^^^^^^^^^^^^^^^^^^^^^^^
TypeError: object NoneType can't be used in 'await' expression
2023-10-19 00:22:43,012 - telegram.ext.Application - ERROR - No error handlers are registered, logging exception.
Traceback (most recent call last):
  File "/Users/nikita/PycharmProjects/pythonProject/venv/lib/python3.11/site-packages/telegram/ext/_application.py", line 1195, in process_update
    await coroutine
  File "/Users/nikita/PycharmProjects/pythonProject/venv/lib/python3.11/site-packages/telegram/ext/_basehandler.py", line 153, in handle_update
    return await self.callback(update, context)
           ^^^^^^^^^^^^^^^^^^^^^^^^^^^^^^^^^^^^
TypeError: object NoneType can't be used in 'await' expression
2023-10-19 00:22:44,409 - telegram.ext.Application - ERROR - No error handlers are registered, logging exception.
Traceback (most recent call last):
  File "/Users/nikita/PycharmProjects/pythonProject/venv/lib/python3.11/site-packages/telegram/ext/_application.py", line 1195, in process_update
    await coroutine
  File "/Users/nikita/PycharmProjects/pythonProject/venv/lib/python3.11/site-packages/telegram/ext/_basehandler.py", line 153, in handle_update
    return await self.callback(update, context)
           ^^^^^^^^^^^^^^^^^^^^^^^^^^^^^^^^^^^^
TypeError: object NoneType can't be used in 'await' expression
2023-10-19 00:23:31,590 - telegram.ext.Application - ERROR - No error handlers are registered, logging exception.
Traceback (most recent call last):
  File "/Users/nikita/PycharmProjects/pythonProject/venv/lib/python3.11/site-packages/telegram/ext/_application.py", line 1195, in process_update
    await coroutine
  File "/Users/nikita/PycharmProjects/pythonProject/venv/lib/python3.11/site-packages/telegram/ext/_basehandler.py", line 153, in handle_update
    return await self.callback(update, context)
           ^^^^^^^^^^^^^^^^^^^^^^^^^^^^^^^^^^^^
TypeError: object NoneType can't be used in 'await' expression
2023-10-19 00:23:33,904 - telegram.ext.Application - ERROR - No error handlers are registered, logging exception.
Traceback (most recent call last):
  File "/Users/nikita/PycharmProjects/pythonProject/venv/lib/python3.11/site-packages/telegram/ext/_application.py", line 1195, in process_update
    await coroutine
  File "/Users/nikita/PycharmProjects/pythonProject/venv/lib/python3.11/site-packages/telegram/ext/_basehandler.py", line 153, in handle_update
    return await self.callback(update, context)
           ^^^^^^^^^^^^^^^^^^^^^^^^^^^^^^^^^^^^
TypeError: object NoneType can't be used in 'await' expression
2023-10-19 00:23:35,102 - telegram.ext.Application - ERROR - No error handlers are registered, logging exception.
Traceback (most recent call last):
  File "/Users/nikita/PycharmProjects/pythonProject/venv/lib/python3.11/site-packages/telegram/ext/_application.py", line 1195, in process_update
    await coroutine
  File "/Users/nikita/PycharmProjects/pythonProject/venv/lib/python3.11/site-packages/telegram/ext/_basehandler.py", line 153, in handle_update
    return await self.callback(update, context)
           ^^^^^^^^^^^^^^^^^^^^^^^^^^^^^^^^^^^^
TypeError: object NoneType can't be used in 'await' expression
2023-10-19 00:23:36,669 - telegram.ext.Application - ERROR - No error handlers are registered, logging exception.
Traceback (most recent call last):
  File "/Users/nikita/PycharmProjects/pythonProject/venv/lib/python3.11/site-packages/telegram/ext/_application.py", line 1195, in process_update
    await coroutine
  File "/Users/nikita/PycharmProjects/pythonProject/venv/lib/python3.11/site-packages/telegram/ext/_basehandler.py", line 153, in handle_update
    return await self.callback(update, context)
           ^^^^^^^^^^^^^^^^^^^^^^^^^^^^^^^^^^^^
TypeError: object NoneType can't be used in 'await' expression
2023-10-19 00:24:07,798 - telegram.ext.Application - ERROR - No error handlers are registered, logging exception.
Traceback (most recent call last):
  File "/Users/nikita/PycharmProjects/pythonProject/venv/lib/python3.11/site-packages/telegram/ext/_application.py", line 1195, in process_update
    await coroutine
  File "/Users/nikita/PycharmProjects/pythonProject/venv/lib/python3.11/site-packages/telegram/ext/_basehandler.py", line 153, in handle_update
    return await self.callback(update, context)
           ^^^^^^^^^^^^^^^^^^^^^^^^^^^^^^^^^^^^
TypeError: object NoneType can't be used in 'await' expression
2023-10-19 00:24:08,787 - telegram.ext.Application - ERROR - No error handlers are registered, logging exception.
Traceback (most recent call last):
  File "/Users/nikita/PycharmProjects/pythonProject/venv/lib/python3.11/site-packages/telegram/ext/_application.py", line 1195, in process_update
    await coroutine
  File "/Users/nikita/PycharmProjects/pythonProject/venv/lib/python3.11/site-packages/telegram/ext/_basehandler.py", line 153, in handle_update
    return await self.callback(update, context)
           ^^^^^^^^^^^^^^^^^^^^^^^^^^^^^^^^^^^^
TypeError: object NoneType can't be used in 'await' expression
2023-10-19 00:24:10,076 - telegram.ext.Application - ERROR - No error handlers are registered, logging exception.
Traceback (most recent call last):
  File "/Users/nikita/PycharmProjects/pythonProject/venv/lib/python3.11/site-packages/telegram/ext/_application.py", line 1195, in process_update
    await coroutine
  File "/Users/nikita/PycharmProjects/pythonProject/venv/lib/python3.11/site-packages/telegram/ext/_basehandler.py", line 153, in handle_update
    return await self.callback(update, context)
           ^^^^^^^^^^^^^^^^^^^^^^^^^^^^^^^^^^^^
TypeError: object NoneType can't be used in 'await' expression
2023-10-19 00:41:11,081 - telegram.ext.Application - ERROR - No error handlers are registered, logging exception.
Traceback (most recent call last):
  File "/Users/nikita/PycharmProjects/L2SH_ADMIN_BOT/venv/lib/python3.11/site-packages/telegram/ext/_application.py", line 1195, in process_update
    await coroutine
  File "/Users/nikita/PycharmProjects/L2SH_ADMIN_BOT/venv/lib/python3.11/site-packages/telegram/ext/_basehandler.py", line 153, in handle_update
    return await self.callback(update, context)
           ^^^^^^^^^^^^^^^^^^^^^^^^^^^^^^^^^^^^
TypeError: object NoneType can't be used in 'await' expression
2023-10-19 00:41:11,087 - telegram.ext.Application - ERROR - No error handlers are registered, logging exception.
Traceback (most recent call last):
  File "/Users/nikita/PycharmProjects/L2SH_ADMIN_BOT/venv/lib/python3.11/site-packages/telegram/ext/_application.py", line 1195, in process_update
    await coroutine
  File "/Users/nikita/PycharmProjects/L2SH_ADMIN_BOT/venv/lib/python3.11/site-packages/telegram/ext/_basehandler.py", line 153, in handle_update
    return await self.callback(update, context)
           ^^^^^^^^^^^^^^^^^^^^^^^^^^^^^^^^^^^^
TypeError: object NoneType can't be used in 'await' expression
2023-10-19 00:41:14,224 - telegram.ext.Application - ERROR - No error handlers are registered, logging exception.
Traceback (most recent call last):
  File "/Users/nikita/PycharmProjects/L2SH_ADMIN_BOT/venv/lib/python3.11/site-packages/telegram/ext/_application.py", line 1195, in process_update
    await coroutine
  File "/Users/nikita/PycharmProjects/L2SH_ADMIN_BOT/venv/lib/python3.11/site-packages/telegram/ext/_basehandler.py", line 153, in handle_update
    return await self.callback(update, context)
           ^^^^^^^^^^^^^^^^^^^^^^^^^^^^^^^^^^^^
TypeError: object NoneType can't be used in 'await' expression
2023-10-19 00:41:15,654 - telegram.ext.Application - ERROR - No error handlers are registered, logging exception.
Traceback (most recent call last):
  File "/Users/nikita/PycharmProjects/L2SH_ADMIN_BOT/venv/lib/python3.11/site-packages/telegram/ext/_application.py", line 1195, in process_update
    await coroutine
  File "/Users/nikita/PycharmProjects/L2SH_ADMIN_BOT/venv/lib/python3.11/site-packages/telegram/ext/_basehandler.py", line 153, in handle_update
    return await self.callback(update, context)
           ^^^^^^^^^^^^^^^^^^^^^^^^^^^^^^^^^^^^
TypeError: object NoneType can't be used in 'await' expression
2023-10-19 00:42:56,795 - telegram.ext.Application - ERROR - No error handlers are registered, logging exception.
Traceback (most recent call last):
  File "/Users/nikita/PycharmProjects/L2SH_ADMIN_BOT/venv/lib/python3.11/site-packages/telegram/ext/_application.py", line 1195, in process_update
    await coroutine
  File "/Users/nikita/PycharmProjects/L2SH_ADMIN_BOT/venv/lib/python3.11/site-packages/telegram/ext/_basehandler.py", line 153, in handle_update
    return await self.callback(update, context)
           ^^^^^^^^^^^^^^^^^^^^^^^^^^^^^^^^^^^^
TypeError: object NoneType can't be used in 'await' expression
2023-10-19 00:42:58,596 - telegram.ext.Application - ERROR - No error handlers are registered, logging exception.
Traceback (most recent call last):
  File "/Users/nikita/PycharmProjects/L2SH_ADMIN_BOT/venv/lib/python3.11/site-packages/telegram/ext/_application.py", line 1195, in process_update
    await coroutine
  File "/Users/nikita/PycharmProjects/L2SH_ADMIN_BOT/venv/lib/python3.11/site-packages/telegram/ext/_basehandler.py", line 153, in handle_update
    return await self.callback(update, context)
           ^^^^^^^^^^^^^^^^^^^^^^^^^^^^^^^^^^^^
TypeError: object NoneType can't be used in 'await' expression
2023-10-19 00:42:59,571 - telegram.ext.Application - ERROR - No error handlers are registered, logging exception.
Traceback (most recent call last):
  File "/Users/nikita/PycharmProjects/L2SH_ADMIN_BOT/venv/lib/python3.11/site-packages/telegram/ext/_application.py", line 1195, in process_update
    await coroutine
  File "/Users/nikita/PycharmProjects/L2SH_ADMIN_BOT/venv/lib/python3.11/site-packages/telegram/ext/_basehandler.py", line 153, in handle_update
    return await self.callback(update, context)
           ^^^^^^^^^^^^^^^^^^^^^^^^^^^^^^^^^^^^
TypeError: object NoneType can't be used in 'await' expression
2023-10-19 00:43:07,710 - telegram.ext.Application - ERROR - No error handlers are registered, logging exception.
Traceback (most recent call last):
  File "/Users/nikita/PycharmProjects/L2SH_ADMIN_BOT/venv/lib/python3.11/site-packages/telegram/ext/_application.py", line 1195, in process_update
    await coroutine
  File "/Users/nikita/PycharmProjects/L2SH_ADMIN_BOT/venv/lib/python3.11/site-packages/telegram/ext/_basehandler.py", line 153, in handle_update
    return await self.callback(update, context)
           ^^^^^^^^^^^^^^^^^^^^^^^^^^^^^^^^^^^^
TypeError: object NoneType can't be used in 'await' expression
2023-10-19 00:43:08,569 - telegram.ext.Application - ERROR - No error handlers are registered, logging exception.
Traceback (most recent call last):
  File "/Users/nikita/PycharmProjects/L2SH_ADMIN_BOT/venv/lib/python3.11/site-packages/telegram/ext/_application.py", line 1195, in process_update
    await coroutine
  File "/Users/nikita/PycharmProjects/L2SH_ADMIN_BOT/venv/lib/python3.11/site-packages/telegram/ext/_basehandler.py", line 153, in handle_update
    return await self.callback(update, context)
           ^^^^^^^^^^^^^^^^^^^^^^^^^^^^^^^^^^^^
TypeError: object NoneType can't be used in 'await' expression
2023-10-19 00:43:12,832 - telegram.ext.Application - ERROR - No error handlers are registered, logging exception.
Traceback (most recent call last):
  File "/Users/nikita/PycharmProjects/L2SH_ADMIN_BOT/venv/lib/python3.11/site-packages/telegram/ext/_application.py", line 1195, in process_update
    await coroutine
  File "/Users/nikita/PycharmProjects/L2SH_ADMIN_BOT/venv/lib/python3.11/site-packages/telegram/ext/_basehandler.py", line 153, in handle_update
    return await self.callback(update, context)
           ^^^^^^^^^^^^^^^^^^^^^^^^^^^^^^^^^^^^
TypeError: object NoneType can't be used in 'await' expression
2023-10-19 00:43:16,661 - telegram.ext.Application - ERROR - No error handlers are registered, logging exception.
Traceback (most recent call last):
  File "/Users/nikita/PycharmProjects/L2SH_ADMIN_BOT/venv/lib/python3.11/site-packages/telegram/ext/_application.py", line 1195, in process_update
    await coroutine
  File "/Users/nikita/PycharmProjects/L2SH_ADMIN_BOT/venv/lib/python3.11/site-packages/telegram/ext/_basehandler.py", line 153, in handle_update
    return await self.callback(update, context)
           ^^^^^^^^^^^^^^^^^^^^^^^^^^^^^^^^^^^^
TypeError: object NoneType can't be used in 'await' expression
2023-10-19 00:43:31,178 - telegram.ext.Application - ERROR - No error handlers are registered, logging exception.
Traceback (most recent call last):
  File "/Users/nikita/PycharmProjects/L2SH_ADMIN_BOT/venv/lib/python3.11/site-packages/telegram/ext/_application.py", line 1195, in process_update
    await coroutine
  File "/Users/nikita/PycharmProjects/L2SH_ADMIN_BOT/venv/lib/python3.11/site-packages/telegram/ext/_basehandler.py", line 153, in handle_update
    return await self.callback(update, context)
           ^^^^^^^^^^^^^^^^^^^^^^^^^^^^^^^^^^^^
TypeError: object NoneType can't be used in 'await' expression
2023-10-19 00:43:32,763 - telegram.ext.Application - ERROR - No error handlers are registered, logging exception.
Traceback (most recent call last):
  File "/Users/nikita/PycharmProjects/L2SH_ADMIN_BOT/venv/lib/python3.11/site-packages/telegram/ext/_application.py", line 1195, in process_update
    await coroutine
  File "/Users/nikita/PycharmProjects/L2SH_ADMIN_BOT/venv/lib/python3.11/site-packages/telegram/ext/_basehandler.py", line 153, in handle_update
    return await self.callback(update, context)
           ^^^^^^^^^^^^^^^^^^^^^^^^^^^^^^^^^^^^
TypeError: object NoneType can't be used in 'await' expression
2023-10-19 00:43:33,880 - telegram.ext.Application - ERROR - No error handlers are registered, logging exception.
Traceback (most recent call last):
  File "/Users/nikita/PycharmProjects/L2SH_ADMIN_BOT/venv/lib/python3.11/site-packages/telegram/ext/_application.py", line 1195, in process_update
    await coroutine
  File "/Users/nikita/PycharmProjects/L2SH_ADMIN_BOT/venv/lib/python3.11/site-packages/telegram/ext/_basehandler.py", line 153, in handle_update
    return await self.callback(update, context)
           ^^^^^^^^^^^^^^^^^^^^^^^^^^^^^^^^^^^^
TypeError: object NoneType can't be used in 'await' expression
2023-10-19 00:43:34,954 - telegram.ext.Application - ERROR - No error handlers are registered, logging exception.
Traceback (most recent call last):
  File "/Users/nikita/PycharmProjects/L2SH_ADMIN_BOT/venv/lib/python3.11/site-packages/telegram/ext/_application.py", line 1195, in process_update
    await coroutine
  File "/Users/nikita/PycharmProjects/L2SH_ADMIN_BOT/venv/lib/python3.11/site-packages/telegram/ext/_basehandler.py", line 153, in handle_update
    return await self.callback(update, context)
           ^^^^^^^^^^^^^^^^^^^^^^^^^^^^^^^^^^^^
TypeError: object NoneType can't be used in 'await' expression
2023-10-19 00:46:21,947 - telegram.ext.Application - ERROR - No error handlers are registered, logging exception.
Traceback (most recent call last):
  File "/Users/nikita/PycharmProjects/L2SH_ADMIN_BOT/venv/lib/python3.11/site-packages/telegram/ext/_application.py", line 1195, in process_update
    await coroutine
  File "/Users/nikita/PycharmProjects/L2SH_ADMIN_BOT/venv/lib/python3.11/site-packages/telegram/ext/_basehandler.py", line 153, in handle_update
    return await self.callback(update, context)
           ^^^^^^^^^^^^^^^^^^^^^^^^^^^^^^^^^^^^
TypeError: object NoneType can't be used in 'await' expression
2023-10-19 00:46:24,121 - telegram.ext.Application - ERROR - No error handlers are registered, logging exception.
Traceback (most recent call last):
  File "/Users/nikita/PycharmProjects/L2SH_ADMIN_BOT/venv/lib/python3.11/site-packages/telegram/ext/_application.py", line 1195, in process_update
    await coroutine
  File "/Users/nikita/PycharmProjects/L2SH_ADMIN_BOT/venv/lib/python3.11/site-packages/telegram/ext/_basehandler.py", line 153, in handle_update
    return await self.callback(update, context)
           ^^^^^^^^^^^^^^^^^^^^^^^^^^^^^^^^^^^^
TypeError: object NoneType can't be used in 'await' expression
2023-10-19 00:46:27,257 - telegram.ext.Application - ERROR - No error handlers are registered, logging exception.
Traceback (most recent call last):
  File "/Users/nikita/PycharmProjects/L2SH_ADMIN_BOT/venv/lib/python3.11/site-packages/telegram/ext/_application.py", line 1195, in process_update
    await coroutine
  File "/Users/nikita/PycharmProjects/L2SH_ADMIN_BOT/venv/lib/python3.11/site-packages/telegram/ext/_basehandler.py", line 153, in handle_update
    return await self.callback(update, context)
           ^^^^^^^^^^^^^^^^^^^^^^^^^^^^^^^^^^^^
TypeError: object NoneType can't be used in 'await' expression
2023-10-19 00:46:28,447 - telegram.ext.Application - ERROR - No error handlers are registered, logging exception.
Traceback (most recent call last):
  File "/Users/nikita/PycharmProjects/L2SH_ADMIN_BOT/venv/lib/python3.11/site-packages/telegram/ext/_application.py", line 1195, in process_update
    await coroutine
  File "/Users/nikita/PycharmProjects/L2SH_ADMIN_BOT/venv/lib/python3.11/site-packages/telegram/ext/_basehandler.py", line 153, in handle_update
    return await self.callback(update, context)
           ^^^^^^^^^^^^^^^^^^^^^^^^^^^^^^^^^^^^
TypeError: object NoneType can't be used in 'await' expression
2023-10-19 00:46:33,564 - telegram.ext.Application - ERROR - No error handlers are registered, logging exception.
Traceback (most recent call last):
  File "/Users/nikita/PycharmProjects/L2SH_ADMIN_BOT/venv/lib/python3.11/site-packages/telegram/ext/_application.py", line 1195, in process_update
    await coroutine
  File "/Users/nikita/PycharmProjects/L2SH_ADMIN_BOT/venv/lib/python3.11/site-packages/telegram/ext/_basehandler.py", line 153, in handle_update
    return await self.callback(update, context)
           ^^^^^^^^^^^^^^^^^^^^^^^^^^^^^^^^^^^^
TypeError: object NoneType can't be used in 'await' expression
2023-10-19 00:46:35,273 - telegram.ext.Application - ERROR - No error handlers are registered, logging exception.
Traceback (most recent call last):
  File "/Users/nikita/PycharmProjects/L2SH_ADMIN_BOT/venv/lib/python3.11/site-packages/telegram/ext/_application.py", line 1195, in process_update
    await coroutine
  File "/Users/nikita/PycharmProjects/L2SH_ADMIN_BOT/venv/lib/python3.11/site-packages/telegram/ext/_basehandler.py", line 153, in handle_update
    return await self.callback(update, context)
           ^^^^^^^^^^^^^^^^^^^^^^^^^^^^^^^^^^^^
TypeError: object NoneType can't be used in 'await' expression
2023-10-19 00:46:36,263 - telegram.ext.Application - ERROR - No error handlers are registered, logging exception.
Traceback (most recent call last):
  File "/Users/nikita/PycharmProjects/L2SH_ADMIN_BOT/venv/lib/python3.11/site-packages/telegram/ext/_application.py", line 1195, in process_update
    await coroutine
  File "/Users/nikita/PycharmProjects/L2SH_ADMIN_BOT/venv/lib/python3.11/site-packages/telegram/ext/_basehandler.py", line 153, in handle_update
    return await self.callback(update, context)
           ^^^^^^^^^^^^^^^^^^^^^^^^^^^^^^^^^^^^
TypeError: object NoneType can't be used in 'await' expression
2023-10-19 01:03:54,118 - telegram.ext.Application - ERROR - No error handlers are registered, logging exception.
Traceback (most recent call last):
  File "/Users/nikita/PycharmProjects/L2SH_ADMIN_BOT/venv/lib/python3.11/site-packages/telegram/ext/_application.py", line 1195, in process_update
    await coroutine
  File "/Users/nikita/PycharmProjects/L2SH_ADMIN_BOT/venv/lib/python3.11/site-packages/telegram/ext/_basehandler.py", line 153, in handle_update
    return await self.callback(update, context)
           ^^^^^^^^^^^^^^^^^^^^^^^^^^^^^^^^^^^^
TypeError: object NoneType can't be used in 'await' expression
2023-10-19 01:04:03,380 - telegram.ext.Application - ERROR - No error handlers are registered, logging exception.
Traceback (most recent call last):
  File "/Users/nikita/PycharmProjects/L2SH_ADMIN_BOT/venv/lib/python3.11/site-packages/telegram/ext/_application.py", line 1195, in process_update
    await coroutine
  File "/Users/nikita/PycharmProjects/L2SH_ADMIN_BOT/venv/lib/python3.11/site-packages/telegram/ext/_basehandler.py", line 153, in handle_update
    return await self.callback(update, context)
           ^^^^^^^^^^^^^^^^^^^^^^^^^^^^^^^^^^^^
TypeError: object NoneType can't be used in 'await' expression
2023-10-19 01:04:11,378 - telegram.ext.Application - ERROR - No error handlers are registered, logging exception.
Traceback (most recent call last):
  File "/Users/nikita/PycharmProjects/L2SH_ADMIN_BOT/venv/lib/python3.11/site-packages/telegram/ext/_application.py", line 1195, in process_update
    await coroutine
  File "/Users/nikita/PycharmProjects/L2SH_ADMIN_BOT/venv/lib/python3.11/site-packages/telegram/ext/_basehandler.py", line 153, in handle_update
    return await self.callback(update, context)
           ^^^^^^^^^^^^^^^^^^^^^^^^^^^^^^^^^^^^
TypeError: object NoneType can't be used in 'await' expression
2023-10-19 01:04:13,675 - telegram.ext.Application - ERROR - No error handlers are registered, logging exception.
Traceback (most recent call last):
  File "/Users/nikita/PycharmProjects/L2SH_ADMIN_BOT/venv/lib/python3.11/site-packages/telegram/ext/_application.py", line 1195, in process_update
    await coroutine
  File "/Users/nikita/PycharmProjects/L2SH_ADMIN_BOT/venv/lib/python3.11/site-packages/telegram/ext/_basehandler.py", line 153, in handle_update
    return await self.callback(update, context)
           ^^^^^^^^^^^^^^^^^^^^^^^^^^^^^^^^^^^^
TypeError: object NoneType can't be used in 'await' expression
2023-10-19 01:04:16,192 - telegram.ext.Application - ERROR - No error handlers are registered, logging exception.
Traceback (most recent call last):
  File "/Users/nikita/PycharmProjects/L2SH_ADMIN_BOT/venv/lib/python3.11/site-packages/telegram/ext/_application.py", line 1195, in process_update
    await coroutine
  File "/Users/nikita/PycharmProjects/L2SH_ADMIN_BOT/venv/lib/python3.11/site-packages/telegram/ext/_basehandler.py", line 153, in handle_update
    return await self.callback(update, context)
           ^^^^^^^^^^^^^^^^^^^^^^^^^^^^^^^^^^^^
TypeError: object NoneType can't be used in 'await' expression
2023-10-19 01:06:13,868 - telegram.ext.Application - ERROR - No error handlers are registered, logging exception.
Traceback (most recent call last):
  File "/Users/nikita/PycharmProjects/L2SH_ADMIN_BOT/venv/lib/python3.11/site-packages/telegram/ext/_application.py", line 1195, in process_update
    await coroutine
  File "/Users/nikita/PycharmProjects/L2SH_ADMIN_BOT/venv/lib/python3.11/site-packages/telegram/ext/_basehandler.py", line 153, in handle_update
    return await self.callback(update, context)
           ^^^^^^^^^^^^^^^^^^^^^^^^^^^^^^^^^^^^
TypeError: object NoneType can't be used in 'await' expression
2023-10-19 01:06:15,536 - telegram.ext.Application - ERROR - No error handlers are registered, logging exception.
Traceback (most recent call last):
  File "/Users/nikita/PycharmProjects/L2SH_ADMIN_BOT/venv/lib/python3.11/site-packages/telegram/ext/_application.py", line 1195, in process_update
    await coroutine
  File "/Users/nikita/PycharmProjects/L2SH_ADMIN_BOT/venv/lib/python3.11/site-packages/telegram/ext/_basehandler.py", line 153, in handle_update
    return await self.callback(update, context)
           ^^^^^^^^^^^^^^^^^^^^^^^^^^^^^^^^^^^^
TypeError: object NoneType can't be used in 'await' expression
2023-10-19 01:06:16,797 - telegram.ext.Application - ERROR - No error handlers are registered, logging exception.
Traceback (most recent call last):
  File "/Users/nikita/PycharmProjects/L2SH_ADMIN_BOT/venv/lib/python3.11/site-packages/telegram/ext/_application.py", line 1195, in process_update
    await coroutine
  File "/Users/nikita/PycharmProjects/L2SH_ADMIN_BOT/venv/lib/python3.11/site-packages/telegram/ext/_basehandler.py", line 153, in handle_update
    return await self.callback(update, context)
           ^^^^^^^^^^^^^^^^^^^^^^^^^^^^^^^^^^^^
TypeError: object NoneType can't be used in 'await' expression
2023-10-19 01:06:17,607 - telegram.ext.Application - ERROR - No error handlers are registered, logging exception.
Traceback (most recent call last):
  File "/Users/nikita/PycharmProjects/L2SH_ADMIN_BOT/venv/lib/python3.11/site-packages/telegram/ext/_application.py", line 1195, in process_update
    await coroutine
  File "/Users/nikita/PycharmProjects/L2SH_ADMIN_BOT/venv/lib/python3.11/site-packages/telegram/ext/_basehandler.py", line 153, in handle_update
    return await self.callback(update, context)
           ^^^^^^^^^^^^^^^^^^^^^^^^^^^^^^^^^^^^
TypeError: object NoneType can't be used in 'await' expression
2023-10-19 01:06:18,402 - telegram.ext.Application - ERROR - No error handlers are registered, logging exception.
Traceback (most recent call last):
  File "/Users/nikita/PycharmProjects/L2SH_ADMIN_BOT/venv/lib/python3.11/site-packages/telegram/ext/_application.py", line 1195, in process_update
    await coroutine
  File "/Users/nikita/PycharmProjects/L2SH_ADMIN_BOT/venv/lib/python3.11/site-packages/telegram/ext/_basehandler.py", line 153, in handle_update
    return await self.callback(update, context)
           ^^^^^^^^^^^^^^^^^^^^^^^^^^^^^^^^^^^^
TypeError: object NoneType can't be used in 'await' expression
2023-10-19 01:27:09,003 - telegram.ext.Application - ERROR - No error handlers are registered, logging exception.
Traceback (most recent call last):
  File "/Users/nikita/PycharmProjects/L2SH_ADMIN_BOT/venv/lib/python3.11/site-packages/telegram/ext/_application.py", line 1195, in process_update
    await coroutine
  File "/Users/nikita/PycharmProjects/L2SH_ADMIN_BOT/venv/lib/python3.11/site-packages/telegram/ext/_basehandler.py", line 153, in handle_update
    return await self.callback(update, context)
           ^^^^^^^^^^^^^^^^^^^^^^^^^^^^^^^^^^^^
TypeError: object NoneType can't be used in 'await' expression
2023-10-19 02:05:36,349 - telegram.ext.Application - ERROR - No error handlers are registered, logging exception.
Traceback (most recent call last):
  File "/Users/nikita/PycharmProjects/L2SH_ADMIN_BOT/venv/lib/python3.11/site-packages/telegram/ext/_application.py", line 1195, in process_update
    await coroutine
  File "/Users/nikita/PycharmProjects/L2SH_ADMIN_BOT/venv/lib/python3.11/site-packages/telegram/ext/_basehandler.py", line 153, in handle_update
    return await self.callback(update, context)
           ^^^^^^^^^^^^^^^^^^^^^^^^^^^^^^^^^^^^
TypeError: object NoneType can't be used in 'await' expression
2023-10-19 02:05:37,545 - telegram.ext.Application - ERROR - No error handlers are registered, logging exception.
Traceback (most recent call last):
  File "/Users/nikita/PycharmProjects/L2SH_ADMIN_BOT/venv/lib/python3.11/site-packages/telegram/ext/_application.py", line 1195, in process_update
    await coroutine
  File "/Users/nikita/PycharmProjects/L2SH_ADMIN_BOT/venv/lib/python3.11/site-packages/telegram/ext/_basehandler.py", line 153, in handle_update
    return await self.callback(update, context)
           ^^^^^^^^^^^^^^^^^^^^^^^^^^^^^^^^^^^^
TypeError: object NoneType can't be used in 'await' expression
2023-10-19 10:51:49,217 - telegram.ext.Application - ERROR - No error handlers are registered, logging exception.
Traceback (most recent call last):
  File "/Users/nikita/PycharmProjects/L2SH_ADMIN_BOT/venv/lib/python3.11/site-packages/telegram/ext/_application.py", line 1195, in process_update
    await coroutine
  File "/Users/nikita/PycharmProjects/L2SH_ADMIN_BOT/venv/lib/python3.11/site-packages/telegram/ext/_basehandler.py", line 153, in handle_update
    return await self.callback(update, context)
           ^^^^^^^^^^^^^^^^^^^^^^^^^^^^^^^^^^^^
TypeError: object NoneType can't be used in 'await' expression
2023-10-19 10:51:50,923 - telegram.ext.Application - ERROR - No error handlers are registered, logging exception.
Traceback (most recent call last):
  File "/Users/nikita/PycharmProjects/L2SH_ADMIN_BOT/venv/lib/python3.11/site-packages/telegram/ext/_application.py", line 1195, in process_update
    await coroutine
  File "/Users/nikita/PycharmProjects/L2SH_ADMIN_BOT/venv/lib/python3.11/site-packages/telegram/ext/_basehandler.py", line 153, in handle_update
    return await self.callback(update, context)
           ^^^^^^^^^^^^^^^^^^^^^^^^^^^^^^^^^^^^
TypeError: object NoneType can't be used in 'await' expression
2023-10-19 15:53:04,931 - telegram.ext.Application - ERROR - No error handlers are registered, logging exception.
Traceback (most recent call last):
  File "/Users/nikita/PycharmProjects/L2SH_ADMIN_BOT/venv/lib/python3.11/site-packages/telegram/ext/_application.py", line 1195, in process_update
    await coroutine
  File "/Users/nikita/PycharmProjects/L2SH_ADMIN_BOT/venv/lib/python3.11/site-packages/telegram/ext/_basehandler.py", line 153, in handle_update
    return await self.callback(update, context)
           ^^^^^^^^^^^^^^^^^^^^^^^^^^^^^^^^^^^^
TypeError: object NoneType can't be used in 'await' expression
2023-10-19 15:53:08,801 - telegram.ext.Application - ERROR - No error handlers are registered, logging exception.
Traceback (most recent call last):
  File "/Users/nikita/PycharmProjects/L2SH_ADMIN_BOT/venv/lib/python3.11/site-packages/telegram/ext/_application.py", line 1195, in process_update
    await coroutine
  File "/Users/nikita/PycharmProjects/L2SH_ADMIN_BOT/venv/lib/python3.11/site-packages/telegram/ext/_basehandler.py", line 153, in handle_update
    return await self.callback(update, context)
           ^^^^^^^^^^^^^^^^^^^^^^^^^^^^^^^^^^^^
TypeError: object NoneType can't be used in 'await' expression
2023-10-19 15:54:00,288 - telegram.ext.Application - ERROR - No error handlers are registered, logging exception.
Traceback (most recent call last):
  File "/Users/nikita/PycharmProjects/L2SH_ADMIN_BOT/venv/lib/python3.11/site-packages/telegram/ext/_application.py", line 1195, in process_update
    await coroutine
  File "/Users/nikita/PycharmProjects/L2SH_ADMIN_BOT/venv/lib/python3.11/site-packages/telegram/ext/_basehandler.py", line 153, in handle_update
    return await self.callback(update, context)
           ^^^^^^^^^^^^^^^^^^^^^^^^^^^^^^^^^^^^
TypeError: object NoneType can't be used in 'await' expression
2023-10-19 19:38:22,421 - telegram.ext.Application - ERROR - No error handlers are registered, logging exception.
Traceback (most recent call last):
  File "/Users/nikita/PycharmProjects/L2SH_ADMIN_BOT/venv/lib/python3.11/site-packages/telegram/ext/_application.py", line 1195, in process_update
    await coroutine
  File "/Users/nikita/PycharmProjects/L2SH_ADMIN_BOT/venv/lib/python3.11/site-packages/telegram/ext/_basehandler.py", line 153, in handle_update
    return await self.callback(update, context)
           ^^^^^^^^^^^^^^^^^^^^^^^^^^^^^^^^^^^^
TypeError: object NoneType can't be used in 'await' expression
2023-10-19 19:38:23,858 - telegram.ext.Application - ERROR - No error handlers are registered, logging exception.
Traceback (most recent call last):
  File "/Users/nikita/PycharmProjects/L2SH_ADMIN_BOT/venv/lib/python3.11/site-packages/telegram/ext/_application.py", line 1195, in process_update
    await coroutine
  File "/Users/nikita/PycharmProjects/L2SH_ADMIN_BOT/venv/lib/python3.11/site-packages/telegram/ext/_basehandler.py", line 153, in handle_update
    return await self.callback(update, context)
           ^^^^^^^^^^^^^^^^^^^^^^^^^^^^^^^^^^^^
TypeError: object NoneType can't be used in 'await' expression
2023-10-19 19:38:56,181 - telegram.ext.Application - ERROR - No error handlers are registered, logging exception.
Traceback (most recent call last):
  File "/Users/nikita/PycharmProjects/L2SH_ADMIN_BOT/venv/lib/python3.11/site-packages/telegram/ext/_application.py", line 1195, in process_update
    await coroutine
  File "/Users/nikita/PycharmProjects/L2SH_ADMIN_BOT/venv/lib/python3.11/site-packages/telegram/ext/_basehandler.py", line 153, in handle_update
    return await self.callback(update, context)
           ^^^^^^^^^^^^^^^^^^^^^^^^^^^^^^^^^^^^
TypeError: object NoneType can't be used in 'await' expression
2023-10-19 19:39:00,719 - telegram.ext.Application - ERROR - No error handlers are registered, logging exception.
Traceback (most recent call last):
  File "/Users/nikita/PycharmProjects/L2SH_ADMIN_BOT/venv/lib/python3.11/site-packages/telegram/ext/_application.py", line 1195, in process_update
    await coroutine
  File "/Users/nikita/PycharmProjects/L2SH_ADMIN_BOT/venv/lib/python3.11/site-packages/telegram/ext/_basehandler.py", line 153, in handle_update
    return await self.callback(update, context)
           ^^^^^^^^^^^^^^^^^^^^^^^^^^^^^^^^^^^^
TypeError: object NoneType can't be used in 'await' expression
2023-10-19 19:39:04,032 - telegram.ext.Application - ERROR - No error handlers are registered, logging exception.
Traceback (most recent call last):
  File "/Users/nikita/PycharmProjects/L2SH_ADMIN_BOT/venv/lib/python3.11/site-packages/telegram/ext/_application.py", line 1195, in process_update
    await coroutine
  File "/Users/nikita/PycharmProjects/L2SH_ADMIN_BOT/venv/lib/python3.11/site-packages/telegram/ext/_basehandler.py", line 153, in handle_update
    return await self.callback(update, context)
           ^^^^^^^^^^^^^^^^^^^^^^^^^^^^^^^^^^^^
TypeError: object NoneType can't be used in 'await' expression
2023-10-19 19:39:17,413 - telegram.ext.Application - ERROR - No error handlers are registered, logging exception.
Traceback (most recent call last):
  File "/Users/nikita/PycharmProjects/L2SH_ADMIN_BOT/venv/lib/python3.11/site-packages/telegram/ext/_application.py", line 1195, in process_update
    await coroutine
  File "/Users/nikita/PycharmProjects/L2SH_ADMIN_BOT/venv/lib/python3.11/site-packages/telegram/ext/_basehandler.py", line 153, in handle_update
    return await self.callback(update, context)
           ^^^^^^^^^^^^^^^^^^^^^^^^^^^^^^^^^^^^
TypeError: object NoneType can't be used in 'await' expression
2023-10-19 19:39:19,076 - telegram.ext.Application - ERROR - No error handlers are registered, logging exception.
Traceback (most recent call last):
  File "/Users/nikita/PycharmProjects/L2SH_ADMIN_BOT/venv/lib/python3.11/site-packages/telegram/ext/_application.py", line 1195, in process_update
    await coroutine
  File "/Users/nikita/PycharmProjects/L2SH_ADMIN_BOT/venv/lib/python3.11/site-packages/telegram/ext/_basehandler.py", line 153, in handle_update
    return await self.callback(update, context)
           ^^^^^^^^^^^^^^^^^^^^^^^^^^^^^^^^^^^^
TypeError: object NoneType can't be used in 'await' expression
2023-10-20 09:01:14,514 - telegram.ext.Application - ERROR - No error handlers are registered, logging exception.
Traceback (most recent call last):
  File "/Users/nikita/PycharmProjects/L2SH_ADMIN_BOT/venv/lib/python3.11/site-packages/telegram/ext/_application.py", line 1195, in process_update
    await coroutine
  File "/Users/nikita/PycharmProjects/L2SH_ADMIN_BOT/venv/lib/python3.11/site-packages/telegram/ext/_basehandler.py", line 153, in handle_update
    return await self.callback(update, context)
           ^^^^^^^^^^^^^^^^^^^^^^^^^^^^^^^^^^^^
TypeError: object NoneType can't be used in 'await' expression
2023-10-20 09:01:15,913 - telegram.ext.Application - ERROR - No error handlers are registered, logging exception.
Traceback (most recent call last):
  File "/Users/nikita/PycharmProjects/L2SH_ADMIN_BOT/venv/lib/python3.11/site-packages/telegram/ext/_application.py", line 1195, in process_update
    await coroutine
  File "/Users/nikita/PycharmProjects/L2SH_ADMIN_BOT/venv/lib/python3.11/site-packages/telegram/ext/_basehandler.py", line 153, in handle_update
    return await self.callback(update, context)
           ^^^^^^^^^^^^^^^^^^^^^^^^^^^^^^^^^^^^
TypeError: object NoneType can't be used in 'await' expression
2023-10-20 09:01:17,376 - telegram.ext.Application - ERROR - No error handlers are registered, logging exception.
Traceback (most recent call last):
  File "/Users/nikita/PycharmProjects/L2SH_ADMIN_BOT/venv/lib/python3.11/site-packages/telegram/ext/_application.py", line 1195, in process_update
    await coroutine
  File "/Users/nikita/PycharmProjects/L2SH_ADMIN_BOT/venv/lib/python3.11/site-packages/telegram/ext/_basehandler.py", line 153, in handle_update
    return await self.callback(update, context)
           ^^^^^^^^^^^^^^^^^^^^^^^^^^^^^^^^^^^^
TypeError: object NoneType can't be used in 'await' expression
2023-10-20 09:01:18,540 - telegram.ext.Application - ERROR - No error handlers are registered, logging exception.
Traceback (most recent call last):
  File "/Users/nikita/PycharmProjects/L2SH_ADMIN_BOT/venv/lib/python3.11/site-packages/telegram/ext/_application.py", line 1195, in process_update
    await coroutine
  File "/Users/nikita/PycharmProjects/L2SH_ADMIN_BOT/venv/lib/python3.11/site-packages/telegram/ext/_basehandler.py", line 153, in handle_update
    return await self.callback(update, context)
           ^^^^^^^^^^^^^^^^^^^^^^^^^^^^^^^^^^^^
TypeError: object NoneType can't be used in 'await' expression
2023-10-20 09:01:19,606 - telegram.ext.Application - ERROR - No error handlers are registered, logging exception.
Traceback (most recent call last):
  File "/Users/nikita/PycharmProjects/L2SH_ADMIN_BOT/venv/lib/python3.11/site-packages/telegram/ext/_application.py", line 1195, in process_update
    await coroutine
  File "/Users/nikita/PycharmProjects/L2SH_ADMIN_BOT/venv/lib/python3.11/site-packages/telegram/ext/_basehandler.py", line 153, in handle_update
    return await self.callback(update, context)
           ^^^^^^^^^^^^^^^^^^^^^^^^^^^^^^^^^^^^
TypeError: object NoneType can't be used in 'await' expression
2023-10-20 09:01:21,378 - telegram.ext.Application - ERROR - No error handlers are registered, logging exception.
Traceback (most recent call last):
  File "/Users/nikita/PycharmProjects/L2SH_ADMIN_BOT/venv/lib/python3.11/site-packages/telegram/ext/_application.py", line 1195, in process_update
    await coroutine
  File "/Users/nikita/PycharmProjects/L2SH_ADMIN_BOT/venv/lib/python3.11/site-packages/telegram/ext/_basehandler.py", line 153, in handle_update
    return await self.callback(update, context)
           ^^^^^^^^^^^^^^^^^^^^^^^^^^^^^^^^^^^^
TypeError: object NoneType can't be used in 'await' expression
2023-10-20 09:01:23,008 - telegram.ext.Application - ERROR - No error handlers are registered, logging exception.
Traceback (most recent call last):
  File "/Users/nikita/PycharmProjects/L2SH_ADMIN_BOT/venv/lib/python3.11/site-packages/telegram/ext/_application.py", line 1195, in process_update
    await coroutine
  File "/Users/nikita/PycharmProjects/L2SH_ADMIN_BOT/venv/lib/python3.11/site-packages/telegram/ext/_basehandler.py", line 153, in handle_update
    return await self.callback(update, context)
           ^^^^^^^^^^^^^^^^^^^^^^^^^^^^^^^^^^^^
TypeError: object NoneType can't be used in 'await' expression
2023-10-20 09:01:23,800 - telegram.ext.Application - ERROR - No error handlers are registered, logging exception.
Traceback (most recent call last):
  File "/Users/nikita/PycharmProjects/L2SH_ADMIN_BOT/venv/lib/python3.11/site-packages/telegram/ext/_application.py", line 1195, in process_update
    await coroutine
  File "/Users/nikita/PycharmProjects/L2SH_ADMIN_BOT/venv/lib/python3.11/site-packages/telegram/ext/_basehandler.py", line 153, in handle_update
    return await self.callback(update, context)
           ^^^^^^^^^^^^^^^^^^^^^^^^^^^^^^^^^^^^
TypeError: object NoneType can't be used in 'await' expression
2023-10-20 09:23:27,006 - telegram.ext.Application - ERROR - No error handlers are registered, logging exception.
Traceback (most recent call last):
  File "/Users/nikita/PycharmProjects/L2SH_ADMIN_BOT/venv/lib/python3.11/site-packages/telegram/ext/_application.py", line 1195, in process_update
    await coroutine
  File "/Users/nikita/PycharmProjects/L2SH_ADMIN_BOT/venv/lib/python3.11/site-packages/telegram/ext/_basehandler.py", line 153, in handle_update
    return await self.callback(update, context)
           ^^^^^^^^^^^^^^^^^^^^^^^^^^^^^^^^^^^^
TypeError: object NoneType can't be used in 'await' expression
2023-10-20 20:19:55,369 - telegram.ext.Application - ERROR - No error handlers are registered, logging exception.
Traceback (most recent call last):
  File "/Users/nikita/PycharmProjects/L2SH_ADMIN_BOT/venv/lib/python3.11/site-packages/telegram/ext/_application.py", line 1195, in process_update
    await coroutine
  File "/Users/nikita/PycharmProjects/L2SH_ADMIN_BOT/venv/lib/python3.11/site-packages/telegram/ext/_basehandler.py", line 153, in handle_update
    return await self.callback(update, context)
           ^^^^^^^^^^^^^^^^^^^^^^^^^^^^^^^^^^^^
TypeError: object NoneType can't be used in 'await' expression
2023-10-20 20:19:56,558 - telegram.ext.Application - ERROR - No error handlers are registered, logging exception.
Traceback (most recent call last):
  File "/Users/nikita/PycharmProjects/L2SH_ADMIN_BOT/venv/lib/python3.11/site-packages/telegram/ext/_application.py", line 1195, in process_update
    await coroutine
  File "/Users/nikita/PycharmProjects/L2SH_ADMIN_BOT/venv/lib/python3.11/site-packages/telegram/ext/_basehandler.py", line 153, in handle_update
    return await self.callback(update, context)
           ^^^^^^^^^^^^^^^^^^^^^^^^^^^^^^^^^^^^
TypeError: object NoneType can't be used in 'await' expression
2023-10-20 21:38:28,457 - telegram.ext.Application - ERROR - No error handlers are registered, logging exception.
Traceback (most recent call last):
  File "/Users/nikita/PycharmProjects/L2SH_ADMIN_BOT/venv/lib/python3.11/site-packages/telegram/ext/_application.py", line 1195, in process_update
    await coroutine
  File "/Users/nikita/PycharmProjects/L2SH_ADMIN_BOT/venv/lib/python3.11/site-packages/telegram/ext/_basehandler.py", line 153, in handle_update
    return await self.callback(update, context)
           ^^^^^^^^^^^^^^^^^^^^^^^^^^^^^^^^^^^^
TypeError: object NoneType can't be used in 'await' expression
2023-10-21 18:55:59,342 - telegram.ext.Application - ERROR - No error handlers are registered, logging exception.
Traceback (most recent call last):
  File "/Users/nikita/PycharmProjects/L2SH_ADMIN_BOT/venv/lib/python3.11/site-packages/telegram/ext/_application.py", line 1195, in process_update
    await coroutine
  File "/Users/nikita/PycharmProjects/L2SH_ADMIN_BOT/venv/lib/python3.11/site-packages/telegram/ext/_basehandler.py", line 153, in handle_update
    return await self.callback(update, context)
           ^^^^^^^^^^^^^^^^^^^^^^^^^^^^^^^^^^^^
TypeError: object NoneType can't be used in 'await' expression
2023-10-21 18:56:00,360 - telegram.ext.Application - ERROR - No error handlers are registered, logging exception.
Traceback (most recent call last):
  File "/Users/nikita/PycharmProjects/L2SH_ADMIN_BOT/venv/lib/python3.11/site-packages/telegram/ext/_application.py", line 1195, in process_update
    await coroutine
  File "/Users/nikita/PycharmProjects/L2SH_ADMIN_BOT/venv/lib/python3.11/site-packages/telegram/ext/_basehandler.py", line 153, in handle_update
    return await self.callback(update, context)
           ^^^^^^^^^^^^^^^^^^^^^^^^^^^^^^^^^^^^
TypeError: object NoneType can't be used in 'await' expression
2023-10-23 17:31:01,412 - telegram.ext.Application - ERROR - No error handlers are registered, logging exception.
Traceback (most recent call last):
  File "/Users/nikita/PycharmProjects/L2SH_ADMIN_BOT/venv/lib/python3.11/site-packages/telegram/ext/_application.py", line 1195, in process_update
    await coroutine
  File "/Users/nikita/PycharmProjects/L2SH_ADMIN_BOT/venv/lib/python3.11/site-packages/telegram/ext/_basehandler.py", line 153, in handle_update
    return await self.callback(update, context)
           ^^^^^^^^^^^^^^^^^^^^^^^^^^^^^^^^^^^^
TypeError: object NoneType can't be used in 'await' expression
2023-10-23 17:31:06,431 - telegram.ext.Application - ERROR - No error handlers are registered, logging exception.
Traceback (most recent call last):
  File "/Users/nikita/PycharmProjects/L2SH_ADMIN_BOT/venv/lib/python3.11/site-packages/telegram/ext/_application.py", line 1195, in process_update
    await coroutine
  File "/Users/nikita/PycharmProjects/L2SH_ADMIN_BOT/venv/lib/python3.11/site-packages/telegram/ext/_basehandler.py", line 153, in handle_update
    return await self.callback(update, context)
           ^^^^^^^^^^^^^^^^^^^^^^^^^^^^^^^^^^^^
TypeError: object NoneType can't be used in 'await' expression
2023-10-23 17:31:16,465 - telegram.ext.Application - ERROR - No error handlers are registered, logging exception.
Traceback (most recent call last):
  File "/Users/nikita/PycharmProjects/L2SH_ADMIN_BOT/venv/lib/python3.11/site-packages/telegram/ext/_application.py", line 1195, in process_update
    await coroutine
  File "/Users/nikita/PycharmProjects/L2SH_ADMIN_BOT/venv/lib/python3.11/site-packages/telegram/ext/_basehandler.py", line 153, in handle_update
    return await self.callback(update, context)
           ^^^^^^^^^^^^^^^^^^^^^^^^^^^^^^^^^^^^
TypeError: object NoneType can't be used in 'await' expression
2023-10-23 17:31:17,089 - telegram.ext.Application - ERROR - No error handlers are registered, logging exception.
Traceback (most recent call last):
  File "/Users/nikita/PycharmProjects/L2SH_ADMIN_BOT/venv/lib/python3.11/site-packages/pandas/core/indexes/base.py", line 3790, in get_loc
    return self._engine.get_loc(casted_key)
           ^^^^^^^^^^^^^^^^^^^^^^^^^^^^^^^^
  File "index.pyx", line 152, in pandas._libs.index.IndexEngine.get_loc
  File "index.pyx", line 181, in pandas._libs.index.IndexEngine.get_loc
  File "pandas/_libs/hashtable_class_helper.pxi", line 7080, in pandas._libs.hashtable.PyObjectHashTable.get_item
  File "pandas/_libs/hashtable_class_helper.pxi", line 7088, in pandas._libs.hashtable.PyObjectHashTable.get_item
KeyError: 'Замена2'

The above exception was the direct cause of the following exception:

Traceback (most recent call last):
  File "/Users/nikita/PycharmProjects/L2SH_ADMIN_BOT/venv/lib/python3.11/site-packages/telegram/ext/_application.py", line 1195, in process_update
    await coroutine
  File "/Users/nikita/PycharmProjects/L2SH_ADMIN_BOT/venv/lib/python3.11/site-packages/telegram/ext/_conversationhandler.py", line 850, in handle_update
    new_state: object = await handler.handle_update(
                        ^^^^^^^^^^^^^^^^^^^^^^^^^^^^
  File "/Users/nikita/PycharmProjects/L2SH_ADMIN_BOT/venv/lib/python3.11/site-packages/telegram/ext/_basehandler.py", line 153, in handle_update
    return await self.callback(update, context)
           ^^^^^^^^^^^^^^^^^^^^^^^^^^^^^^^^^^^^
  File "/Users/nikita/PycharmProjects/L2SH_ADMIN_BOT/l2sh_bot/class_load_timetable.py", line 113, in load_pdf
    await save_edits_in_timetable_csv(context.user_data['changes_date'])
  File "/Users/nikita/PycharmProjects/L2SH_ADMIN_BOT/l2sh_bot/funcs_back.py", line 254, in save_edits_in_timetable_csv
    df['Замены'] = df['Замены'] + '//' + df['Замена2']
                                         ~~^^^^^^^^^^^
  File "/Users/nikita/PycharmProjects/L2SH_ADMIN_BOT/venv/lib/python3.11/site-packages/pandas/core/frame.py", line 3896, in __getitem__
    indexer = self.columns.get_loc(key)
              ^^^^^^^^^^^^^^^^^^^^^^^^^
  File "/Users/nikita/PycharmProjects/L2SH_ADMIN_BOT/venv/lib/python3.11/site-packages/pandas/core/indexes/base.py", line 3797, in get_loc
    raise KeyError(key) from err
KeyError: 'Замена2'
