2023-10-19 00:22:04,737 - telegram.ext.Application - ERROR - No error handlers are registered, logging exception.
Traceback (most recent call last):
  File "/Users/nikita/PycharmProjects/pythonProject/venv/lib/python3.11/site-packages/telegram/ext/_application.py", line 1195, in process_update
    await coroutine
  File "/Users/nikita/PycharmProjects/pythonProject/venv/lib/python3.11/site-packages/telegram/ext/_basehandler.py", line 153, in handle_update
    return await self.callback(update, context)
           ^^^^^^^^^^^^^^^^^^^^^^^^^^^^^^^^^^^^
TypeError: object NoneType can't be used in 'await' expression
2023-10-19 00:22:06,346 - telegram.ext.Application - ERROR - No error handlers are registered, logging exception.
Traceback (most recent call last):
  File "/Users/nikita/PycharmProjects/pythonProject/venv/lib/python3.11/site-packages/telegram/ext/_application.py", line 1195, in process_update
    await coroutine
  File "/Users/nikita/PycharmProjects/pythonProject/venv/lib/python3.11/site-packages/telegram/ext/_basehandler.py", line 153, in handle_update
    return await self.callback(update, context)
           ^^^^^^^^^^^^^^^^^^^^^^^^^^^^^^^^^^^^
TypeError: object NoneType can't be used in 'await' expression
2023-10-19 00:22:07,337 - telegram.ext.Application - ERROR - No error handlers are registered, logging exception.
Traceback (most recent call last):
  File "/Users/nikita/PycharmProjects/pythonProject/venv/lib/python3.11/site-packages/telegram/ext/_application.py", line 1195, in process_update
    await coroutine
  File "/Users/nikita/PycharmProjects/pythonProject/venv/lib/python3.11/site-packages/telegram/ext/_basehandler.py", line 153, in handle_update
    return await self.callback(update, context)
           ^^^^^^^^^^^^^^^^^^^^^^^^^^^^^^^^^^^^
TypeError: object NoneType can't be used in 'await' expression
2023-10-19 00:22:40,042 - telegram.ext.Application - ERROR - No error handlers are registered, logging exception.
Traceback (most recent call last):
  File "/Users/nikita/PycharmProjects/pythonProject/venv/lib/python3.11/site-packages/telegram/ext/_application.py", line 1195, in process_update
    await coroutine
  File "/Users/nikita/PycharmProjects/pythonProject/venv/lib/python3.11/site-packages/telegram/ext/_basehandler.py", line 153, in handle_update
    return await self.callback(update, context)
           ^^^^^^^^^^^^^^^^^^^^^^^^^^^^^^^^^^^^
TypeError: object NoneType can't be used in 'await' expression
2023-10-19 00:22:41,553 - telegram.ext.Application - ERROR - No error handlers are registered, logging exception.
Traceback (most recent call last):
  File "/Users/nikita/PycharmProjects/pythonProject/venv/lib/python3.11/site-packages/telegram/ext/_application.py", line 1195, in process_update
    await coroutine
  File "/Users/nikita/PycharmProjects/pythonProject/venv/lib/python3.11/site-packages/telegram/ext/_basehandler.py", line 153, in handle_update
    return await self.callback(update, context)
           ^^^^^^^^^^^^^^^^^^^^^^^^^^^^^^^^^^^^
TypeError: object NoneType can't be used in 'await' expression
2023-10-19 00:22:42,353 - telegram.ext.Application - ERROR - No error handlers are registered, logging exception.
Traceback (most recent call last):
  File "/Users/nikita/PycharmProjects/pythonProject/venv/lib/python3.11/site-packages/telegram/ext/_application.py", line 1195, in process_update
    await coroutine
  File "/Users/nikita/PycharmProjects/pythonProject/venv/lib/python3.11/site-packages/telegram/ext/_basehandler.py", line 153, in handle_update
    return await self.callback(update, context)
           ^^^^^^^^^^^^^^^^^^^^^^^^^^^^^^^^^^^^
TypeError: object NoneType can't be used in 'await' expression
2023-10-19 00:22:43,012 - telegram.ext.Application - ERROR - No error handlers are registered, logging exception.
Traceback (most recent call last):
  File "/Users/nikita/PycharmProjects/pythonProject/venv/lib/python3.11/site-packages/telegram/ext/_application.py", line 1195, in process_update
    await coroutine
  File "/Users/nikita/PycharmProjects/pythonProject/venv/lib/python3.11/site-packages/telegram/ext/_basehandler.py", line 153, in handle_update
    return await self.callback(update, context)
           ^^^^^^^^^^^^^^^^^^^^^^^^^^^^^^^^^^^^
TypeError: object NoneType can't be used in 'await' expression
2023-10-19 00:22:44,409 - telegram.ext.Application - ERROR - No error handlers are registered, logging exception.
Traceback (most recent call last):
  File "/Users/nikita/PycharmProjects/pythonProject/venv/lib/python3.11/site-packages/telegram/ext/_application.py", line 1195, in process_update
    await coroutine
  File "/Users/nikita/PycharmProjects/pythonProject/venv/lib/python3.11/site-packages/telegram/ext/_basehandler.py", line 153, in handle_update
    return await self.callback(update, context)
           ^^^^^^^^^^^^^^^^^^^^^^^^^^^^^^^^^^^^
TypeError: object NoneType can't be used in 'await' expression
2023-10-19 00:23:31,590 - telegram.ext.Application - ERROR - No error handlers are registered, logging exception.
Traceback (most recent call last):
  File "/Users/nikita/PycharmProjects/pythonProject/venv/lib/python3.11/site-packages/telegram/ext/_application.py", line 1195, in process_update
    await coroutine
  File "/Users/nikita/PycharmProjects/pythonProject/venv/lib/python3.11/site-packages/telegram/ext/_basehandler.py", line 153, in handle_update
    return await self.callback(update, context)
           ^^^^^^^^^^^^^^^^^^^^^^^^^^^^^^^^^^^^
TypeError: object NoneType can't be used in 'await' expression
2023-10-19 00:23:33,904 - telegram.ext.Application - ERROR - No error handlers are registered, logging exception.
Traceback (most recent call last):
  File "/Users/nikita/PycharmProjects/pythonProject/venv/lib/python3.11/site-packages/telegram/ext/_application.py", line 1195, in process_update
    await coroutine
  File "/Users/nikita/PycharmProjects/pythonProject/venv/lib/python3.11/site-packages/telegram/ext/_basehandler.py", line 153, in handle_update
    return await self.callback(update, context)
           ^^^^^^^^^^^^^^^^^^^^^^^^^^^^^^^^^^^^
TypeError: object NoneType can't be used in 'await' expression
2023-10-19 00:23:35,102 - telegram.ext.Application - ERROR - No error handlers are registered, logging exception.
Traceback (most recent call last):
  File "/Users/nikita/PycharmProjects/pythonProject/venv/lib/python3.11/site-packages/telegram/ext/_application.py", line 1195, in process_update
    await coroutine
  File "/Users/nikita/PycharmProjects/pythonProject/venv/lib/python3.11/site-packages/telegram/ext/_basehandler.py", line 153, in handle_update
    return await self.callback(update, context)
           ^^^^^^^^^^^^^^^^^^^^^^^^^^^^^^^^^^^^
TypeError: object NoneType can't be used in 'await' expression
2023-10-19 00:23:36,669 - telegram.ext.Application - ERROR - No error handlers are registered, logging exception.
Traceback (most recent call last):
  File "/Users/nikita/PycharmProjects/pythonProject/venv/lib/python3.11/site-packages/telegram/ext/_application.py", line 1195, in process_update
    await coroutine
  File "/Users/nikita/PycharmProjects/pythonProject/venv/lib/python3.11/site-packages/telegram/ext/_basehandler.py", line 153, in handle_update
    return await self.callback(update, context)
           ^^^^^^^^^^^^^^^^^^^^^^^^^^^^^^^^^^^^
TypeError: object NoneType can't be used in 'await' expression
2023-10-19 00:24:07,798 - telegram.ext.Application - ERROR - No error handlers are registered, logging exception.
Traceback (most recent call last):
  File "/Users/nikita/PycharmProjects/pythonProject/venv/lib/python3.11/site-packages/telegram/ext/_application.py", line 1195, in process_update
    await coroutine
  File "/Users/nikita/PycharmProjects/pythonProject/venv/lib/python3.11/site-packages/telegram/ext/_basehandler.py", line 153, in handle_update
    return await self.callback(update, context)
           ^^^^^^^^^^^^^^^^^^^^^^^^^^^^^^^^^^^^
TypeError: object NoneType can't be used in 'await' expression
2023-10-19 00:24:08,787 - telegram.ext.Application - ERROR - No error handlers are registered, logging exception.
Traceback (most recent call last):
  File "/Users/nikita/PycharmProjects/pythonProject/venv/lib/python3.11/site-packages/telegram/ext/_application.py", line 1195, in process_update
    await coroutine
  File "/Users/nikita/PycharmProjects/pythonProject/venv/lib/python3.11/site-packages/telegram/ext/_basehandler.py", line 153, in handle_update
    return await self.callback(update, context)
           ^^^^^^^^^^^^^^^^^^^^^^^^^^^^^^^^^^^^
TypeError: object NoneType can't be used in 'await' expression
2023-10-19 00:24:10,076 - telegram.ext.Application - ERROR - No error handlers are registered, logging exception.
Traceback (most recent call last):
  File "/Users/nikita/PycharmProjects/pythonProject/venv/lib/python3.11/site-packages/telegram/ext/_application.py", line 1195, in process_update
    await coroutine
  File "/Users/nikita/PycharmProjects/pythonProject/venv/lib/python3.11/site-packages/telegram/ext/_basehandler.py", line 153, in handle_update
    return await self.callback(update, context)
           ^^^^^^^^^^^^^^^^^^^^^^^^^^^^^^^^^^^^
TypeError: object NoneType can't be used in 'await' expression
